<?xml version="1.0" encoding="utf-8"?>
<!-- This URDF was automatically created by SolidWorks to URDF Exporter! Originally created by Stephen Brawner (brawner@gmail.com) 
     Commit Version: 1.6.0-4-g7f85cfe  Build Version: 1.6.7995.38578
     For more information, please see http://wiki.ros.org/sw_urdf_exporter -->
<robot
  name="quadped_urdf">
  <link
    name="base_link">
    <inertial>
      <origin
        xyz="0.000199869485857869 0.000556619002151084 0.00469963496815284"
        rpy="0 0 0" />
      <mass
        value="0.670811138520923" />
      <inertia
        ixx="0.000375618663416432"
        ixy="2.42317909402465E-08"
        ixz="4.33100484218247E-06"
        iyy="0.000838609036708274"
        iyz="5.47863479312491E-07"
        izz="0.000624542308718559" />
    </inertial>
    <visual>
      <origin
        xyz="0 0 0"
        rpy="0 0 0" />
      <geometry>
        <mesh
          filename="package://quadped_urdf/meshes/base_link.STL" />
      </geometry>
      <material
        name="">
        <color
          rgba="0.752941176470588 0.752941176470588 0.752941176470588 1" />
      </material>
    </visual>
    <collision>
      <origin
        xyz="0 0 0"
        rpy="0 0 0" />
      <geometry>
        <mesh
          filename="package://quadped_urdf/meshes/base_link.STL" />
      </geometry>
    </collision>
  </link>
  <link
    name="fe_1">
    <inertial>
      <origin
        xyz="0.000133784347622304 4.77330235079005E-05 0.106028370145983"
        rpy="0 0 0" />
      <mass
        value="0.0410869722409442" />
      <inertia
        ixx="0.00011531160730975"
        ixy="1.29677045975409E-08"
        ixz="2.07977871016147E-07"
        iyy="0.000110878132321103"
        iyz="1.25387573590273E-07"
        izz="8.60693868056784E-06" />
    </inertial>
    <visual>
      <origin
        xyz="0 0 0"
        rpy="0 0 0" />
      <geometry>
        <mesh
          filename="package://quadped_urdf/meshes/fe_1.STL" />
      </geometry>
      <material
        name="">
        <color
          rgba="0.466666666666667 0.733333333333333 1 1" />
      </material>
    </visual>
    <collision>
      <origin
        xyz="0 0 0"
        rpy="0 0 0" />
      <geometry>
        <mesh
          filename="package://quadped_urdf/meshes/fe_1.STL" />
      </geometry>
    </collision>
  </link>
  <joint
    name="fixed_fe_joint1"
    type="continuous">
    <origin
      xyz="0.0875 0 0.02955"
      rpy="0 0 0" />
    <parent
      link="base_link" />
    <child
      link="fe_1" />
    <axis
      xyz="0 0 1" />
  </joint>
  <link
    name="upper_1">
    <inertial>
      <origin
        xyz="-0.0597384086105178 -0.0577400488263468 -0.0211210718210717"
        rpy="0 0 0" />
      <mass
        value="0.0446543406730976" />
      <inertia
        ixx="7.77450392778894E-05"
        ixy="-6.95025591666466E-05"
        ixz="-7.26036146442219E-06"
        iyy="8.27688720251678E-05"
        iyz="-7.00120031315984E-06"
        izz="0.00015285801774174" />
    </inertial>
    <visual>
      <origin
        xyz="0 0 0"
        rpy="0 0 0" />
      <geometry>
        <mesh
          filename="package://quadped_urdf/meshes/upper_1.STL" />
      </geometry>
      <material
        name="">
        <color
          rgba="0.619607843137255 0.807843137254902 1 1" />
      </material>
    </visual>
    <collision>
      <origin
        xyz="0 0 0"
        rpy="0 0 0" />
      <geometry>
        <mesh
          filename="package://quadped_urdf/meshes/upper_1.STL" />
      </geometry>
    </collision>
  </link>
  <joint
    name="fe_upper_1"
    type="continuous">
    <origin
      xyz="0.014 0 0.1648"
      rpy="3.14159265358979 -1.5707963267949 0" />
    <parent
      link="fe_1" />
    <child
      link="upper_1" />
    <axis
      xyz="0 0 1" />
  </joint>
  <link
    name="lower_1">
    <inertial>
      <origin
        xyz="-0.0451015746230226 -0.0511635786738877 0.0071128841582116"
        rpy="0 0 0" />
      <mass
        value="0.0342018777935593" />
      <inertia
        ixx="5.78661077701089E-05"
        ixy="-4.96017387584486E-05"
        ixz="1.2917130837338E-06"
        iyy="4.53223712452692E-05"
        iyz="1.46532747000408E-06"
        izz="0.000102339922101355" />
    </inertial>
    <visual>
      <origin
        xyz="0 0 0"
        rpy="0 0 0" />
      <geometry>
        <mesh
          filename="package://quadped_urdf/meshes/lower_1.STL" />
      </geometry>
      <material
        name="">
        <color
          rgba="0.466666666666667 0.733333333333333 1 1" />
      </material>
    </visual>
    <collision>
      <origin
        xyz="0 0 0"
        rpy="0 0 0" />
      <geometry>
        <mesh
          filename="package://quadped_urdf/meshes/lower_1.STL" />
      </geometry>
    </collision>
  </link>
  <joint
    name="upper_lower1"
    type="continuous">
    <origin
      xyz="-0.115099296377973 -0.111140235723614 -0.037449999892348"
      rpy="3.14159265358979 0 3.14159265358979" />
    <parent
      link="upper_1" />
    <child
      link="lower_1" />
    <axis
      xyz="0 0 -1" />
  </joint>
  <link
    name="fe_2">
    <inertial>
      <origin
        xyz="0.000133783663271922 -4.77318376975103E-05 -0.120628370705068"
        rpy="0 0 0" />
      <mass
        value="0.0410869680075753" />
      <inertia
        ixx="0.000115311606588616"
        ixy="-1.29680490679935E-08"
        ixz="-2.07977716884497E-07"
        iyy="0.00011087813235385"
        iyz="1.25387311435636E-07"
        izz="8.60693825829928E-06" />
    </inertial>
    <visual>
      <origin
        xyz="0 0 0"
        rpy="0 0 0" />
      <geometry>
        <mesh
          filename="package://quadped_urdf/meshes/fe_2.STL" />
      </geometry>
      <material
        name="">
        <color
          rgba="0.466666666666667 0.733333333333333 1 1" />
      </material>
    </visual>
    <collision>
      <origin
        xyz="0 0 0"
        rpy="0 0 0" />
      <geometry>
        <mesh
          filename="package://quadped_urdf/meshes/fe_2.STL" />
      </geometry>
    </collision>
  </link>
  <joint
    name="fixed_fe2"
    type="continuous">
    <origin
      xyz="0.0875 0 -0.01505"
      rpy="0 0 0" />
    <parent
      link="base_link" />
    <child
      link="fe_2" />
    <axis
      xyz="0 0 -1" />
  </joint>
  <link
    name="upper_2">
    <inertial>
      <origin
        xyz="0.0589909759927409 -0.0585038831685175 -0.0211210807910604"
        rpy="0 0 0" />
      <mass
        value="0.0446542245768807" />
      <inertia
        ixx="7.98280498328104E-05"
        ixy="6.95465211209788E-05"
        ixz="7.1532103850981E-06"
        iyy="8.06879995257044E-05"
        iyz="-7.11064311154229E-06"
        izz="0.000152857828919439" />
    </inertial>
    <visual>
      <origin
        xyz="0 0 0"
        rpy="0 0 0" />
      <geometry>
        <mesh
          filename="package://quadped_urdf/meshes/upper_2.STL" />
      </geometry>
      <material
        name="">
        <color
          rgba="0.619607843137255 0.807843137254902 1 1" />
      </material>
    </visual>
    <collision>
      <origin
        xyz="0 0 0"
        rpy="0 0 0" />
      <geometry>
        <mesh
          filename="package://quadped_urdf/meshes/upper_2.STL" />
      </geometry>
    </collision>
  </link>
  <joint
    name="fe_upper2"
    type="continuous">
    <origin
      xyz="0.014 0 -0.1794"
      rpy="3.14159265358979 -1.5707963267949 0" />
    <parent
      link="fe_2" />
    <child
      link="upper_2" />
    <axis
      xyz="0 0 1" />
  </joint>
  <link
    name="lower_2">
    <inertial>
      <origin
        xyz="0.0488250783006519 -0.0476232678429994 0.00711288414141042"
        rpy="0 0 0" />
      <mass
        value="0.0342018770763651" />
      <inertia
        ixx="5.03484849740801E-05"
        ixy="4.99811652852977E-05"
        ixz="-1.39835266732097E-06"
        iyy="5.28399931282873E-05"
        iyz="1.36393449757027E-06"
        izz="0.000102339921207292" />
    </inertial>
    <visual>
      <origin
        xyz="0 0 0"
        rpy="0 0 0" />
      <geometry>
        <mesh
          filename="package://quadped_urdf/meshes/lower_2.STL" />
      </geometry>
      <material
        name="">
        <color
          rgba="0.466666666666667 0.733333333333333 1 1" />
      </material>
    </visual>
    <collision>
      <origin
        xyz="0 0 0"
        rpy="0 0 0" />
      <geometry>
        <mesh
          filename="package://quadped_urdf/meshes/lower_2.STL" />
      </geometry>
    </collision>
  </link>
  <joint
    name="upper_lower2"
    type="continuous">
    <origin
      xyz="0.113550017656808 -0.11272263975711 -0.0374499998987262"
      rpy="-3.14159265358979 0 -3.14159265358979" />
    <parent
      link="upper_2" />
    <child
      link="lower_2" />
    <axis
      xyz="0 0 -1" />
  </joint>
  <link
    name="fe_3">
    <inertial>
      <origin
        xyz="-0.000133784343773896 -4.77306488392214E-05 0.120628370198019"
        rpy="0 0 0" />
      <mass
        value="0.0410869722175319" />
      <inertia
        ixx="0.00011531160729402"
        ixy="1.29683942005516E-08"
        ixz="-2.07977852336387E-07"
        iyy="0.000110878131679831"
        iyz="-1.2538706892328E-07"
        izz="8.60693806694117E-06" />
    </inertial>
    <visual>
      <origin
        xyz="0 0 0"
        rpy="0 0 0" />
      <geometry>
        <mesh
          filename="package://quadped_urdf/meshes/fe_3.STL" />
      </geometry>
      <material
        name="">
        <color
          rgba="0.466666666666667 0.733333333333333 1 1" />
      </material>
    </visual>
    <collision>
      <origin
        xyz="0 0 0"
        rpy="0 0 0" />
      <geometry>
        <mesh
          filename="package://quadped_urdf/meshes/fe_3.STL" />
      </geometry>
    </collision>
  </link>
  <joint
    name="fixed_fe3"
    type="continuous">
    <origin
      xyz="-0.0875 0 0.0150499999999999"
      rpy="0 0 0" />
    <parent
      link="base_link" />
    <child
      link="fe_3" />
    <axis
      xyz="0 0 1" />
  </joint>
  <link
    name="upper_3">
    <inertial>
      <origin
        xyz="-0.0604981268118873 -0.0569429106565106 0.0211209869663977"
        rpy="0 0 0" />
      <mass
        value="0.0446546348773634" />
      <inertia
        ixx="7.61977883784226E-05"
        ixy="-6.94292608686278E-05"
        ixz="7.33647161233422E-06"
        iyy="8.43186953376684E-05"
        iyz="6.92142192601393E-06"
        izz="0.000152857887920906" />
    </inertial>
    <visual>
      <origin
        xyz="0 0 0"
        rpy="0 0 0" />
      <geometry>
        <mesh
          filename="package://quadped_urdf/meshes/upper_3.STL" />
      </geometry>
      <material
        name="">
        <color
          rgba="0.619607843137255 0.807843137254902 1 1" />
      </material>
    </visual>
    <collision>
      <origin
        xyz="0 0 0"
        rpy="0 0 0" />
      <geometry>
        <mesh
          filename="package://quadped_urdf/meshes/upper_3.STL" />
      </geometry>
    </collision>
  </link>
  <joint
    name="fe_upper3"
    type="continuous">
    <origin
      xyz="-0.014 0 0.1794"
      rpy="3.14159265358979 -1.5707963267949 0" />
    <parent
      link="fe_3" />
    <child
      link="upper_3" />
    <axis
      xyz="0 0 -1" />
  </joint>
  <link
    name="lower_3">
    <inertial>
      <origin
        xyz="-0.0442900756867695 -0.0518676504095001 -0.00711288434835652"
        rpy="0 0 0" />
      <mass
        value="0.0342018772349896" />
      <inertia
        ixx="5.94254807461177E-05"
        ixy="-4.93795547324207E-05"
        ixz="-1.26846981761219E-06"
        iyy="4.37629968314577E-05"
        iyz="-1.48549381364917E-06"
        izz="0.000102339920764835" />
    </inertial>
    <visual>
      <origin
        xyz="0 0 0"
        rpy="0 0 0" />
      <geometry>
        <mesh
          filename="package://quadped_urdf/meshes/lower_3.STL" />
      </geometry>
      <material
        name="">
        <color
          rgba="0.466666666666667 0.733333333333333 1 1" />
      </material>
    </visual>
    <collision>
      <origin
        xyz="0 0 0"
        rpy="0 0 0" />
      <geometry>
        <mesh
          filename="package://quadped_urdf/meshes/lower_3.STL" />
      </geometry>
    </collision>
  </link>
  <joint
    name="upper_lower3"
    type="continuous">
    <origin
      xyz="-0.116454958715717 -0.109718925397384 0.0374499999982159"
      rpy="3.14159265358979 0 -3.14159265358979" />
    <parent
      link="upper_3" />
    <child
      link="lower_3" />
    <axis
      xyz="0 0 1" />
  </joint>
  <link
    name="fe_4">
    <inertial>
      <origin
        xyz="-0.000133784244345653 4.77307753636163E-05 -0.105878371015855"
        rpy="0 0 0" />
      <mass
        value="0.0410869728202433" />
      <inertia
        ixx="0.000115311609365403"
        ixy="-1.29684323868918E-08"
        ixz="2.07978100591953E-07"
        iyy="0.000110878134389651"
        iyz="-1.25386757701034E-07"
        izz="8.60693880041462E-06" />
    </inertial>
    <visual>
      <origin
        xyz="0 0 0"
        rpy="0 0 0" />
      <geometry>
        <mesh
          filename="package://quadped_urdf/meshes/fe_4.STL" />
      </geometry>
      <material
        name="">
        <color
          rgba="0.466666666666667 0.733333333333333 1 1" />
      </material>
    </visual>
    <collision>
      <origin
        xyz="0 0 0"
        rpy="0 0 0" />
      <geometry>
        <mesh
          filename="package://quadped_urdf/meshes/fe_4.STL" />
      </geometry>
    </collision>
  </link>
  <joint
    name="fixed_fe4"
    type="continuous">
    <origin
      xyz="-0.0875 0 -0.0297"
      rpy="0 0 0" />
    <parent
      link="base_link" />
    <child
      link="fe_4" />
    <axis
      xyz="0 0 -1" />
  </joint>
  <link
    name="upper_4">
    <inertial>
      <origin
        xyz="0.0559181010152732 -0.0614465869752386 0.0211209824502505"
        rpy="0 0 0" />
      <mass
        value="0.0446546254311322" />
      <inertia
        ixx="8.66459519584787E-05"
        ixy="6.9253565215849E-05"
        ixz="-6.7971455511834E-06"
        iyy="7.38627775858064E-05"
        iyz="7.45176677363446E-06"
        izz="0.000152857864044894" />
    </inertial>
    <visual>
      <origin
        xyz="0 0 0"
        rpy="0 0 0" />
      <geometry>
        <mesh
          filename="package://quadped_urdf/meshes/upper_4.STL" />
      </geometry>
      <material
        name="">
        <color
          rgba="0.619607843137255 0.807843137254902 1 1" />
      </material>
    </visual>
    <collision>
      <origin
        xyz="0 0 0"
        rpy="0 0 0" />
      <geometry>
        <mesh
          filename="package://quadped_urdf/meshes/upper_4.STL" />
      </geometry>
    </collision>
  </link>
  <joint
    name="fe_upper4"
    type="continuous">
    <origin
      xyz="-0.014 0 -0.16465"
      rpy="3.14159265358979 -1.5707963267949 0" />
    <parent
      link="fe_4" />
    <child
      link="upper_4" />
    <axis
      xyz="0 0 -1" />
  </joint>
  <link
    name="lower_4">
    <inertial>
      <origin
        xyz="0.0492622082174013 -0.047170952259612 -0.00711288432869739"
        rpy="0 0 0" />
      <mass
        value="0.0342018774179522" />
      <inertia
        ixx="4.94267586230462E-05"
        ixy="4.99496830473901E-05"
        ixz="1.41087382739234E-06"
        iyy="5.37617198399135E-05"
        iyz="-1.3509783468548E-06"
        izz="0.000102339921625709" />
    </inertial>
    <visual>
      <origin
        xyz="0 0 0"
        rpy="0 0 0" />
      <geometry>
        <mesh
          filename="package://quadped_urdf/meshes/lower_4.STL" />
      </geometry>
      <material
        name="">
        <color
          rgba="0.466666666666667 0.733333333333333 1 1" />
      </material>
    </visual>
    <collision>
      <origin
        xyz="0 0 0"
        rpy="0 0 0" />
      <geometry>
        <mesh
          filename="package://quadped_urdf/meshes/lower_4.STL" />
      </geometry>
    </collision>
  </link>
  <joint
    name="upper_lower4"
    type="continuous">
    <origin
      xyz="0.107746216734634 -0.118282512568206 0.0374500000013904"
      rpy="3.14159265358979 0 -3.14159265358979" />
    <parent
      link="upper_4" />
    <child
      link="lower_4" />
    <axis
      xyz="0 0 1" />
  </joint>
</robot>